[2025-08-04T14:20:39.278+0000] {logging_mixin.py:188} INFO - Changing /opt/***/logs/dag_id=load_random_users_to_rds/run_id=manual__2025-08-04T14:20:29.254489+00:00/task_id=load_users_to_rds permission to 509
[2025-08-04T14:20:39.410+0000] {logging_mixin.py:188} INFO - Changing /opt/***/logs/dag_id=load_random_users_to_rds/run_id=manual__2025-08-04T14:20:29.254489+00:00/task_id=load_users_to_rds permission to 509
[2025-08-04T14:20:39.529+0000] {taskinstance.py:1956} INFO - Dependencies all met for dep_context=non-requeueable deps ti=<TaskInstance: load_random_users_to_rds.load_users_to_rds manual__2025-08-04T14:20:29.254489+00:00 [queued]>
[2025-08-04T14:20:39.549+0000] {taskinstance.py:1956} INFO - Dependencies all met for dep_context=requeueable deps ti=<TaskInstance: load_random_users_to_rds.load_users_to_rds manual__2025-08-04T14:20:29.254489+00:00 [queued]>
[2025-08-04T14:20:39.551+0000] {taskinstance.py:2170} INFO - Starting attempt 1 of 2
[2025-08-04T14:20:39.582+0000] {taskinstance.py:2191} INFO - Executing <Task(PythonOperator): load_users_to_rds> on 2025-08-04 14:20:29.254489+00:00
[2025-08-04T14:20:39.597+0000] {standard_task_runner.py:60} INFO - Started process 236 to run task
[2025-08-04T14:20:39.608+0000] {standard_task_runner.py:87} INFO - Running: ['***', 'tasks', 'run', 'load_random_users_to_rds', 'load_users_to_rds', 'manual__2025-08-04T14:20:29.254489+00:00', '--job-id', '5', '--raw', '--subdir', 'DAGS_FOLDER/user.py', '--cfg-path', '/tmp/tmpzfql_agj']
[2025-08-04T14:20:39.615+0000] {standard_task_runner.py:88} INFO - Job 5: Subtask load_users_to_rds
[2025-08-04T14:20:39.787+0000] {logging_mixin.py:188} INFO - Changing /opt/***/logs/dag_id=load_random_users_to_rds/run_id=manual__2025-08-04T14:20:29.254489+00:00/task_id=load_users_to_rds permission to 509
[2025-08-04T14:20:39.815+0000] {task_command.py:423} INFO - Running <TaskInstance: load_random_users_to_rds.load_users_to_rds manual__2025-08-04T14:20:29.254489+00:00 [running]> on host 9edf237adf6e
[2025-08-04T14:20:40.054+0000] {taskinstance.py:2480} INFO - Exporting env vars: AIRFLOW_CTX_DAG_OWNER='***' AIRFLOW_CTX_DAG_ID='load_random_users_to_rds' AIRFLOW_CTX_TASK_ID='load_users_to_rds' AIRFLOW_CTX_EXECUTION_DATE='2025-08-04T14:20:29.254489+00:00' AIRFLOW_CTX_TRY_NUMBER='1' AIRFLOW_CTX_DAG_RUN_ID='manual__2025-08-04T14:20:29.254489+00:00'
[2025-08-04T14:20:52.704+0000] {taskinstance.py:2698} ERROR - Task failed with exception
Traceback (most recent call last):
  File "/home/airflow/.local/lib/python3.8/site-packages/pymysql/connections.py", line 649, in connect
    sock = socket.create_connection(
  File "/usr/local/lib/python3.8/socket.py", line 808, in create_connection
    raise err
  File "/usr/local/lib/python3.8/socket.py", line 796, in create_connection
    sock.connect(sa)
socket.timeout: timed out

During handling of the above exception, another exception occurred:

Traceback (most recent call last):
  File "/home/airflow/.local/lib/python3.8/site-packages/airflow/models/taskinstance.py", line 433, in _execute_task
    result = execute_callable(context=context, **execute_callable_kwargs)
  File "/home/airflow/.local/lib/python3.8/site-packages/airflow/operators/python.py", line 199, in execute
    return_value = self.execute_callable()
  File "/home/airflow/.local/lib/python3.8/site-packages/airflow/operators/python.py", line 216, in execute_callable
    return self.python_callable(*self.op_args, **self.op_kwargs)
  File "/opt/airflow/dags/randomuser.py", line 37, in load_users_to_rds
    conn = pymysql.connect(
  File "/home/airflow/.local/lib/python3.8/site-packages/pymysql/connections.py", line 361, in __init__
    self.connect()
  File "/home/airflow/.local/lib/python3.8/site-packages/pymysql/connections.py", line 716, in connect
    raise exc
pymysql.err.OperationalError: (2003, "Can't connect to MySQL server on 'dev-rds-instance.c5am0m0g8h3k.eu-west-1.rds.amazonaws.com' (timed out)")
[2025-08-04T14:20:52.920+0000] {taskinstance.py:1138} INFO - Marking task as UP_FOR_RETRY. dag_id=load_random_users_to_rds, task_id=load_users_to_rds, execution_date=20250804T142029, start_date=20250804T142039, end_date=20250804T142052
[2025-08-04T14:20:52.989+0000] {standard_task_runner.py:107} ERROR - Failed to execute job 5 for task load_users_to_rds ((2003, "Can't connect to MySQL server on 'dev-rds-instance.c5am0m0g8h3k.eu-west-1.rds.amazonaws.com' (timed out)"); 236)
[2025-08-04T14:20:53.052+0000] {local_task_job_runner.py:234} INFO - Task exited with return code 1
[2025-08-04T14:20:53.105+0000] {taskinstance.py:3280} INFO - 0 downstream tasks scheduled from follow-on schedule check
