[2025-08-04T14:31:43.415+0000] {logging_mixin.py:188} INFO - Changing /opt/***/logs/dag_id=load_random_users_to_rds/run_id=manual__2025-08-04T14:20:29.254489+00:00/task_id=load_users_to_rds permission to 509
[2025-08-04T14:31:43.484+0000] {logging_mixin.py:188} INFO - Changing /opt/***/logs/dag_id=load_random_users_to_rds/run_id=manual__2025-08-04T14:20:29.254489+00:00/task_id=load_users_to_rds permission to 509
[2025-08-04T14:31:43.540+0000] {taskinstance.py:1956} INFO - Dependencies all met for dep_context=non-requeueable deps ti=<TaskInstance: load_random_users_to_rds.load_users_to_rds manual__2025-08-04T14:20:29.254489+00:00 [queued]>
[2025-08-04T14:31:43.559+0000] {taskinstance.py:1956} INFO - Dependencies all met for dep_context=requeueable deps ti=<TaskInstance: load_random_users_to_rds.load_users_to_rds manual__2025-08-04T14:20:29.254489+00:00 [queued]>
[2025-08-04T14:31:43.560+0000] {taskinstance.py:2170} INFO - Starting attempt 4 of 5
[2025-08-04T14:31:43.602+0000] {taskinstance.py:2191} INFO - Executing <Task(PythonOperator): load_users_to_rds> on 2025-08-04 14:20:29.254489+00:00
[2025-08-04T14:31:43.624+0000] {standard_task_runner.py:60} INFO - Started process 391 to run task
[2025-08-04T14:31:43.633+0000] {standard_task_runner.py:87} INFO - Running: ['***', 'tasks', 'run', 'load_random_users_to_rds', 'load_users_to_rds', 'manual__2025-08-04T14:20:29.254489+00:00', '--job-id', '10', '--raw', '--subdir', 'DAGS_FOLDER/user.py', '--cfg-path', '/tmp/tmp_t12hdv9']
[2025-08-04T14:31:43.660+0000] {standard_task_runner.py:88} INFO - Job 10: Subtask load_users_to_rds
[2025-08-04T14:31:43.857+0000] {logging_mixin.py:188} INFO - Changing /opt/***/logs/dag_id=load_random_users_to_rds/run_id=manual__2025-08-04T14:20:29.254489+00:00/task_id=load_users_to_rds permission to 509
[2025-08-04T14:31:43.888+0000] {task_command.py:423} INFO - Running <TaskInstance: load_random_users_to_rds.load_users_to_rds manual__2025-08-04T14:20:29.254489+00:00 [running]> on host 9edf237adf6e
[2025-08-04T14:31:44.120+0000] {taskinstance.py:2480} INFO - Exporting env vars: AIRFLOW_CTX_DAG_OWNER='***' AIRFLOW_CTX_DAG_ID='load_random_users_to_rds' AIRFLOW_CTX_TASK_ID='load_users_to_rds' AIRFLOW_CTX_EXECUTION_DATE='2025-08-04T14:20:29.254489+00:00' AIRFLOW_CTX_TRY_NUMBER='4' AIRFLOW_CTX_DAG_RUN_ID='manual__2025-08-04T14:20:29.254489+00:00'
[2025-08-04T14:31:46.705+0000] {taskinstance.py:2698} ERROR - Task failed with exception
Traceback (most recent call last):
  File "/home/airflow/.local/lib/python3.8/site-packages/airflow/models/taskinstance.py", line 433, in _execute_task
    result = execute_callable(context=context, **execute_callable_kwargs)
  File "/home/airflow/.local/lib/python3.8/site-packages/airflow/operators/python.py", line 199, in execute
    return_value = self.execute_callable()
  File "/home/airflow/.local/lib/python3.8/site-packages/airflow/operators/python.py", line 216, in execute_callable
    return self.python_callable(*self.op_args, **self.op_kwargs)
  File "/opt/airflow/dags/randomuser.py", line 37, in load_users_to_rds
    conn = pymysql.connect(
  File "/home/airflow/.local/lib/python3.8/site-packages/pymysql/connections.py", line 361, in __init__
    self.connect()
  File "/home/airflow/.local/lib/python3.8/site-packages/pymysql/connections.py", line 669, in connect
    self._request_authentication()
  File "/home/airflow/.local/lib/python3.8/site-packages/pymysql/connections.py", line 957, in _request_authentication
    auth_packet = self._read_packet()
  File "/home/airflow/.local/lib/python3.8/site-packages/pymysql/connections.py", line 775, in _read_packet
    packet.raise_for_error()
  File "/home/airflow/.local/lib/python3.8/site-packages/pymysql/protocol.py", line 219, in raise_for_error
    err.raise_mysql_exception(self._data)
  File "/home/airflow/.local/lib/python3.8/site-packages/pymysql/err.py", line 150, in raise_mysql_exception
    raise errorclass(errno, errval)
pymysql.err.OperationalError: (1049, "Unknown database 'rdsdb'")
[2025-08-04T14:31:46.739+0000] {taskinstance.py:1138} INFO - Marking task as UP_FOR_RETRY. dag_id=load_random_users_to_rds, task_id=load_users_to_rds, execution_date=20250804T142029, start_date=20250804T143143, end_date=20250804T143146
[2025-08-04T14:31:46.777+0000] {standard_task_runner.py:107} ERROR - Failed to execute job 10 for task load_users_to_rds ((1049, "Unknown database 'rdsdb'"); 391)
[2025-08-04T14:31:46.825+0000] {local_task_job_runner.py:234} INFO - Task exited with return code 1
[2025-08-04T14:31:46.870+0000] {taskinstance.py:3280} INFO - 0 downstream tasks scheduled from follow-on schedule check
