[2025-08-04T14:35:22.933+0000] {logging_mixin.py:188} INFO - Changing /opt/***/logs/dag_id=load_random_users_to_rds/run_id=manual__2025-08-04T14:33:06.802009+00:00/task_id=load_users_to_rds permission to 509
[2025-08-04T14:35:23.061+0000] {logging_mixin.py:188} INFO - Changing /opt/***/logs/dag_id=load_random_users_to_rds/run_id=manual__2025-08-04T14:33:06.802009+00:00/task_id=load_users_to_rds permission to 509
[2025-08-04T14:35:23.201+0000] {taskinstance.py:1956} INFO - Dependencies all met for dep_context=non-requeueable deps ti=<TaskInstance: load_random_users_to_rds.load_users_to_rds manual__2025-08-04T14:33:06.802009+00:00 [queued]>
[2025-08-04T14:35:23.253+0000] {taskinstance.py:1956} INFO - Dependencies all met for dep_context=requeueable deps ti=<TaskInstance: load_random_users_to_rds.load_users_to_rds manual__2025-08-04T14:33:06.802009+00:00 [queued]>
[2025-08-04T14:35:23.257+0000] {taskinstance.py:2170} INFO - Starting attempt 2 of 2
[2025-08-04T14:35:23.317+0000] {taskinstance.py:2191} INFO - Executing <Task(PythonOperator): load_users_to_rds> on 2025-08-04 14:33:06.802009+00:00
[2025-08-04T14:35:23.336+0000] {standard_task_runner.py:60} INFO - Started process 450 to run task
[2025-08-04T14:35:23.345+0000] {standard_task_runner.py:87} INFO - Running: ['***', 'tasks', 'run', 'load_random_users_to_rds', 'load_users_to_rds', 'manual__2025-08-04T14:33:06.802009+00:00', '--job-id', '13', '--raw', '--subdir', 'DAGS_FOLDER/user.py', '--cfg-path', '/tmp/tmp07krshi5']
[2025-08-04T14:35:23.351+0000] {standard_task_runner.py:88} INFO - Job 13: Subtask load_users_to_rds
[2025-08-04T14:35:23.486+0000] {logging_mixin.py:188} INFO - Changing /opt/***/logs/dag_id=load_random_users_to_rds/run_id=manual__2025-08-04T14:33:06.802009+00:00/task_id=load_users_to_rds permission to 509
[2025-08-04T14:35:23.507+0000] {task_command.py:423} INFO - Running <TaskInstance: load_random_users_to_rds.load_users_to_rds manual__2025-08-04T14:33:06.802009+00:00 [running]> on host 9edf237adf6e
[2025-08-04T14:35:23.764+0000] {taskinstance.py:2480} INFO - Exporting env vars: AIRFLOW_CTX_DAG_OWNER='***' AIRFLOW_CTX_DAG_ID='load_random_users_to_rds' AIRFLOW_CTX_TASK_ID='load_users_to_rds' AIRFLOW_CTX_EXECUTION_DATE='2025-08-04T14:33:06.802009+00:00' AIRFLOW_CTX_TRY_NUMBER='2' AIRFLOW_CTX_DAG_RUN_ID='manual__2025-08-04T14:33:06.802009+00:00'
[2025-08-04T14:35:28.554+0000] {taskinstance.py:2698} ERROR - Task failed with exception
Traceback (most recent call last):
  File "/home/airflow/.local/lib/python3.8/site-packages/airflow/models/taskinstance.py", line 433, in _execute_task
    result = execute_callable(context=context, **execute_callable_kwargs)
  File "/home/airflow/.local/lib/python3.8/site-packages/airflow/operators/python.py", line 199, in execute
    return_value = self.execute_callable()
  File "/home/airflow/.local/lib/python3.8/site-packages/airflow/operators/python.py", line 216, in execute_callable
    return self.python_callable(*self.op_args, **self.op_kwargs)
  File "/opt/airflow/dags/randomuser.py", line 37, in load_users_to_rds
    conn = pymysql.connect(
  File "/home/airflow/.local/lib/python3.8/site-packages/pymysql/connections.py", line 361, in __init__
    self.connect()
  File "/home/airflow/.local/lib/python3.8/site-packages/pymysql/connections.py", line 669, in connect
    self._request_authentication()
  File "/home/airflow/.local/lib/python3.8/site-packages/pymysql/connections.py", line 957, in _request_authentication
    auth_packet = self._read_packet()
  File "/home/airflow/.local/lib/python3.8/site-packages/pymysql/connections.py", line 775, in _read_packet
    packet.raise_for_error()
  File "/home/airflow/.local/lib/python3.8/site-packages/pymysql/protocol.py", line 219, in raise_for_error
    err.raise_mysql_exception(self._data)
  File "/home/airflow/.local/lib/python3.8/site-packages/pymysql/err.py", line 150, in raise_mysql_exception
    raise errorclass(errno, errval)
pymysql.err.OperationalError: (1049, "Unknown database 'rdsdb'")
[2025-08-04T14:35:28.588+0000] {taskinstance.py:1138} INFO - Marking task as FAILED. dag_id=load_random_users_to_rds, task_id=load_users_to_rds, execution_date=20250804T143306, start_date=20250804T143523, end_date=20250804T143528
[2025-08-04T14:35:28.608+0000] {standard_task_runner.py:107} ERROR - Failed to execute job 13 for task load_users_to_rds ((1049, "Unknown database 'rdsdb'"); 450)
[2025-08-04T14:35:28.648+0000] {local_task_job_runner.py:234} INFO - Task exited with return code 1
[2025-08-04T14:35:28.671+0000] {taskinstance.py:3280} INFO - 0 downstream tasks scheduled from follow-on schedule check
