[2025-08-01T23:35:00.652+0000] {logging_mixin.py:188} INFO - Changing /opt/***/logs/dag_id=cdr_pipeline/run_id=manual__2025-08-01T23:26:21.805709+00:00/task_id=load_to_redshift permission to 509
[2025-08-01T23:35:00.715+0000] {logging_mixin.py:188} INFO - Changing /opt/***/logs/dag_id=cdr_pipeline/run_id=manual__2025-08-01T23:26:21.805709+00:00/task_id=load_to_redshift permission to 509
[2025-08-01T23:35:00.753+0000] {taskinstance.py:1956} INFO - Dependencies all met for dep_context=non-requeueable deps ti=<TaskInstance: cdr_pipeline.load_to_redshift manual__2025-08-01T23:26:21.805709+00:00 [queued]>
[2025-08-01T23:35:00.764+0000] {taskinstance.py:1956} INFO - Dependencies all met for dep_context=requeueable deps ti=<TaskInstance: cdr_pipeline.load_to_redshift manual__2025-08-01T23:26:21.805709+00:00 [queued]>
[2025-08-01T23:35:00.766+0000] {taskinstance.py:2170} INFO - Starting attempt 3 of 4
[2025-08-01T23:35:00.783+0000] {taskinstance.py:2191} INFO - Executing <Task(S3ToRedshiftOperator): load_to_redshift> on 2025-08-01 23:26:21.805709+00:00
[2025-08-01T23:35:00.793+0000] {standard_task_runner.py:60} INFO - Started process 511 to run task
[2025-08-01T23:35:00.800+0000] {standard_task_runner.py:87} INFO - Running: ['***', 'tasks', 'run', 'cdr_pipeline', 'load_to_redshift', 'manual__2025-08-01T23:26:21.805709+00:00', '--job-id', '54', '--raw', '--subdir', 'DAGS_FOLDER/dag.py', '--cfg-path', '/tmp/tmp0npfcj7u']
[2025-08-01T23:35:00.802+0000] {standard_task_runner.py:88} INFO - Job 54: Subtask load_to_redshift
[2025-08-01T23:35:00.888+0000] {logging_mixin.py:188} INFO - Changing /opt/***/logs/dag_id=cdr_pipeline/run_id=manual__2025-08-01T23:26:21.805709+00:00/task_id=load_to_redshift permission to 509
[2025-08-01T23:35:00.906+0000] {task_command.py:423} INFO - Running <TaskInstance: cdr_pipeline.load_to_redshift manual__2025-08-01T23:26:21.805709+00:00 [running]> on host 1524a7d8e0b3
[2025-08-01T23:35:01.044+0000] {taskinstance.py:2480} INFO - Exporting env vars: AIRFLOW_CTX_DAG_OWNER='***' AIRFLOW_CTX_DAG_ID='cdr_pipeline' AIRFLOW_CTX_TASK_ID='load_to_redshift' AIRFLOW_CTX_EXECUTION_DATE='2025-08-01T23:26:21.805709+00:00' AIRFLOW_CTX_TRY_NUMBER='3' AIRFLOW_CTX_DAG_RUN_ID='manual__2025-08-01T23:26:21.805709+00:00'
[2025-08-01T23:35:01.060+0000] {base.py:83} INFO - Using connection ID 'aws_default' for task execution.
[2025-08-01T23:35:01.070+0000] {base.py:83} INFO - Using connection ID 'aws_default' for task execution.
[2025-08-01T23:35:01.072+0000] {connection_wrapper.py:378} INFO - AWS Connection (conn_id='aws_default', conn_type='aws') credentials retrieved from login and password.
[2025-08-01T23:35:01.087+0000] {s3_to_redshift.py:192} INFO - Executing COPY command...
[2025-08-01T23:35:01.096+0000] {base_aws.py:581} WARNING - Unable to find AWS Connection ID 'redshift_default', switching to empty.
[2025-08-01T23:35:01.097+0000] {base_aws.py:161} INFO - No connection ID provided. Fallback on boto3 credential strategy (region_name=None). See: https://boto3.amazonaws.com/v1/documentation/api/latest/guide/configuration.html
[2025-08-01T23:35:02.164+0000] {taskinstance.py:2698} ERROR - Task failed with exception
Traceback (most recent call last):
  File "/home/airflow/.local/lib/python3.8/site-packages/airflow/models/taskinstance.py", line 433, in _execute_task
    result = execute_callable(context=context, **execute_callable_kwargs)
  File "/home/airflow/.local/lib/python3.8/site-packages/airflow/providers/amazon/aws/transfers/s3_to_redshift.py", line 194, in execute
    redshift_hook.execute_query(sql=sql, **self.redshift_data_api_kwargs)
  File "/home/airflow/.local/lib/python3.8/site-packages/airflow/providers/amazon/aws/hooks/redshift_data.py", line 99, in execute_query
    resp = self.conn.execute_statement(**trim_none_values(kwargs))
  File "/home/airflow/.local/lib/python3.8/site-packages/botocore/client.py", line 553, in _api_call
    return self._make_api_call(operation_name, kwargs)
  File "/home/airflow/.local/lib/python3.8/site-packages/botocore/client.py", line 989, in _make_api_call
    http, parsed_response = self._make_request(
  File "/home/airflow/.local/lib/python3.8/site-packages/botocore/client.py", line 1015, in _make_request
    return self._endpoint.make_request(operation_model, request_dict)
  File "/home/airflow/.local/lib/python3.8/site-packages/botocore/endpoint.py", line 119, in make_request
    return self._send_request(request_dict, operation_model)
  File "/home/airflow/.local/lib/python3.8/site-packages/botocore/endpoint.py", line 198, in _send_request
    request = self.create_request(request_dict, operation_model)
  File "/home/airflow/.local/lib/python3.8/site-packages/botocore/endpoint.py", line 134, in create_request
    self._event_emitter.emit(
  File "/home/airflow/.local/lib/python3.8/site-packages/botocore/hooks.py", line 412, in emit
    return self._emitter.emit(aliased_event_name, **kwargs)
  File "/home/airflow/.local/lib/python3.8/site-packages/botocore/hooks.py", line 256, in emit
    return self._emit(event_name, kwargs)
  File "/home/airflow/.local/lib/python3.8/site-packages/botocore/hooks.py", line 239, in _emit
    response = handler(**kwargs)
  File "/home/airflow/.local/lib/python3.8/site-packages/botocore/signers.py", line 105, in handler
    return self.sign(operation_name, request)
  File "/home/airflow/.local/lib/python3.8/site-packages/botocore/signers.py", line 195, in sign
    auth.add_auth(request)
  File "/home/airflow/.local/lib/python3.8/site-packages/botocore/auth.py", line 418, in add_auth
    raise NoCredentialsError()
botocore.exceptions.NoCredentialsError: Unable to locate credentials
[2025-08-01T23:35:02.178+0000] {taskinstance.py:1138} INFO - Marking task as UP_FOR_RETRY. dag_id=cdr_pipeline, task_id=load_to_redshift, execution_date=20250801T232621, start_date=20250801T233500, end_date=20250801T233502
[2025-08-01T23:35:02.207+0000] {standard_task_runner.py:107} ERROR - Failed to execute job 54 for task load_to_redshift (Unable to locate credentials; 511)
[2025-08-01T23:35:02.266+0000] {local_task_job_runner.py:234} INFO - Task exited with return code 1
[2025-08-01T23:35:02.296+0000] {taskinstance.py:3280} INFO - 0 downstream tasks scheduled from follow-on schedule check
