[2025-08-04T14:53:40.623+0000] {logging_mixin.py:188} INFO - Changing /opt/***/logs/dag_id=cdr_pipeline/run_id=scheduled__2025-07-23T00:00:00+00:00/task_id=load_to_redshift permission to 509
[2025-08-04T14:53:40.954+0000] {logging_mixin.py:188} INFO - Changing /opt/***/logs/dag_id=cdr_pipeline/run_id=scheduled__2025-07-23T00:00:00+00:00/task_id=load_to_redshift permission to 509
[2025-08-04T14:53:41.210+0000] {taskinstance.py:1956} INFO - Dependencies all met for dep_context=non-requeueable deps ti=<TaskInstance: cdr_pipeline.load_to_redshift scheduled__2025-07-23T00:00:00+00:00 [queued]>
[2025-08-04T14:53:41.376+0000] {taskinstance.py:1956} INFO - Dependencies all met for dep_context=requeueable deps ti=<TaskInstance: cdr_pipeline.load_to_redshift scheduled__2025-07-23T00:00:00+00:00 [queued]>
[2025-08-04T14:53:41.401+0000] {taskinstance.py:2170} INFO - Starting attempt 2 of 2
[2025-08-04T14:53:41.986+0000] {taskinstance.py:2191} INFO - Executing <Task(S3ToRedshiftOperator): load_to_redshift> on 2025-07-23 00:00:00+00:00
[2025-08-04T14:53:42.120+0000] {standard_task_runner.py:60} INFO - Started process 853 to run task
[2025-08-04T14:53:42.274+0000] {standard_task_runner.py:87} INFO - Running: ['***', 'tasks', 'run', 'cdr_pipeline', 'load_to_redshift', 'scheduled__2025-07-23T00:00:00+00:00', '--job-id', '59', '--raw', '--subdir', 'DAGS_FOLDER/dag.py', '--cfg-path', '/tmp/tmp2u3ug2dp']
[2025-08-04T14:53:42.306+0000] {standard_task_runner.py:88} INFO - Job 59: Subtask load_to_redshift
[2025-08-04T14:53:43.902+0000] {logging_mixin.py:188} INFO - Changing /opt/***/logs/dag_id=cdr_pipeline/run_id=scheduled__2025-07-23T00:00:00+00:00/task_id=load_to_redshift permission to 509
[2025-08-04T14:53:43.934+0000] {task_command.py:423} INFO - Running <TaskInstance: cdr_pipeline.load_to_redshift scheduled__2025-07-23T00:00:00+00:00 [running]> on host 9edf237adf6e
[2025-08-04T14:53:45.274+0000] {taskinstance.py:2480} INFO - Exporting env vars: AIRFLOW_CTX_DAG_OWNER='***' AIRFLOW_CTX_DAG_ID='cdr_pipeline' AIRFLOW_CTX_TASK_ID='load_to_redshift' AIRFLOW_CTX_EXECUTION_DATE='2025-07-23T00:00:00+00:00' AIRFLOW_CTX_TRY_NUMBER='2' AIRFLOW_CTX_DAG_RUN_ID='scheduled__2025-07-23T00:00:00+00:00'
[2025-08-04T14:53:45.479+0000] {base.py:83} INFO - Using connection ID 'aws_default' for task execution.
[2025-08-04T14:53:45.583+0000] {base.py:83} INFO - Using connection ID 'aws_default' for task execution.
[2025-08-04T14:53:45.597+0000] {connection_wrapper.py:378} INFO - AWS Connection (conn_id='aws_default', conn_type='aws') credentials retrieved from login and password.
[2025-08-04T14:53:45.864+0000] {s3_to_redshift.py:192} INFO - Executing COPY command...
[2025-08-04T14:53:46.001+0000] {base.py:83} INFO - Using connection ID 'redshift_default' for task execution.
[2025-08-04T14:53:46.009+0000] {connection_wrapper.py:378} INFO - AWS Connection (conn_id='redshift_default', conn_type='aws') credentials retrieved from login and password.
[2025-08-04T14:53:57.332+0000] {taskinstance.py:2698} ERROR - Task failed with exception
Traceback (most recent call last):
  File "/home/airflow/.local/lib/python3.8/site-packages/airflow/models/taskinstance.py", line 433, in _execute_task
    result = execute_callable(context=context, **execute_callable_kwargs)
  File "/home/airflow/.local/lib/python3.8/site-packages/airflow/providers/amazon/aws/transfers/s3_to_redshift.py", line 194, in execute
    redshift_hook.execute_query(sql=sql, **self.redshift_data_api_kwargs)
  File "/home/airflow/.local/lib/python3.8/site-packages/airflow/providers/amazon/aws/hooks/redshift_data.py", line 99, in execute_query
    resp = self.conn.execute_statement(**trim_none_values(kwargs))
  File "/home/airflow/.local/lib/python3.8/site-packages/botocore/client.py", line 553, in _api_call
    return self._make_api_call(operation_name, kwargs)
  File "/home/airflow/.local/lib/python3.8/site-packages/botocore/client.py", line 1009, in _make_api_call
    raise error_class(parsed_response, operation_name)
botocore.errorfactory.ValidationException: An error occurred (ValidationException) when calling the ExecuteStatement operation: Redshift endpoint is not available.
[2025-08-04T14:53:57.392+0000] {taskinstance.py:1138} INFO - Marking task as FAILED. dag_id=cdr_pipeline, task_id=load_to_redshift, execution_date=20250723T000000, start_date=20250804T145341, end_date=20250804T145357
[2025-08-04T14:53:57.584+0000] {standard_task_runner.py:107} ERROR - Failed to execute job 59 for task load_to_redshift (An error occurred (ValidationException) when calling the ExecuteStatement operation: Redshift endpoint is not available.; 853)
[2025-08-04T14:53:58.008+0000] {local_task_job_runner.py:234} INFO - Task exited with return code 1
[2025-08-04T14:53:58.226+0000] {taskinstance.py:3280} INFO - 0 downstream tasks scheduled from follow-on schedule check
