[2025-08-01T22:33:33.124+0000] {logging_mixin.py:188} INFO - Changing /opt/***/logs/dag_id=cdr_pipeline/run_id=manual__2025-08-01T20:53:47.782452+00:00/task_id=load_to_s3 permission to 509
[2025-08-01T22:33:33.201+0000] {logging_mixin.py:188} INFO - Changing /opt/***/logs/dag_id=cdr_pipeline/run_id=manual__2025-08-01T20:53:47.782452+00:00/task_id=load_to_s3 permission to 509
[2025-08-01T22:33:33.260+0000] {taskinstance.py:1956} INFO - Dependencies all met for dep_context=non-requeueable deps ti=<TaskInstance: cdr_pipeline.load_to_s3 manual__2025-08-01T20:53:47.782452+00:00 [queued]>
[2025-08-01T22:33:33.274+0000] {taskinstance.py:1956} INFO - Dependencies all met for dep_context=requeueable deps ti=<TaskInstance: cdr_pipeline.load_to_s3 manual__2025-08-01T20:53:47.782452+00:00 [queued]>
[2025-08-01T22:33:33.276+0000] {taskinstance.py:2170} INFO - Starting attempt 6 of 7
[2025-08-01T22:33:33.303+0000] {taskinstance.py:2191} INFO - Executing <Task(PythonOperator): load_to_s3> on 2025-08-01 20:53:47.782452+00:00
[2025-08-01T22:33:33.318+0000] {standard_task_runner.py:60} INFO - Started process 2522 to run task
[2025-08-01T22:33:33.326+0000] {standard_task_runner.py:87} INFO - Running: ['***', 'tasks', 'run', 'cdr_pipeline', 'load_to_s3', 'manual__2025-08-01T20:53:47.782452+00:00', '--job-id', '27', '--raw', '--subdir', 'DAGS_FOLDER/dag.py', '--cfg-path', '/tmp/tmpd6xjj50z']
[2025-08-01T22:33:33.332+0000] {standard_task_runner.py:88} INFO - Job 27: Subtask load_to_s3
[2025-08-01T22:33:33.454+0000] {logging_mixin.py:188} INFO - Changing /opt/***/logs/dag_id=cdr_pipeline/run_id=manual__2025-08-01T20:53:47.782452+00:00/task_id=load_to_s3 permission to 509
[2025-08-01T22:33:33.472+0000] {task_command.py:423} INFO - Running <TaskInstance: cdr_pipeline.load_to_s3 manual__2025-08-01T20:53:47.782452+00:00 [running]> on host 99c5562df5f8
[2025-08-01T22:33:33.615+0000] {taskinstance.py:2480} INFO - Exporting env vars: AIRFLOW_CTX_DAG_OWNER='***' AIRFLOW_CTX_DAG_ID='cdr_pipeline' AIRFLOW_CTX_TASK_ID='load_to_s3' AIRFLOW_CTX_EXECUTION_DATE='2025-08-01T20:53:47.782452+00:00' AIRFLOW_CTX_TRY_NUMBER='6' AIRFLOW_CTX_DAG_RUN_ID='manual__2025-08-01T20:53:47.782452+00:00'
[2025-08-01T22:33:37.054+0000] {taskinstance.py:2698} ERROR - Task failed with exception
Traceback (most recent call last):
  File "/home/airflow/.local/lib/python3.8/site-packages/airflow/models/taskinstance.py", line 433, in _execute_task
    result = execute_callable(context=context, **execute_callable_kwargs)
  File "/home/airflow/.local/lib/python3.8/site-packages/airflow/operators/python.py", line 199, in execute
    return_value = self.execute_callable()
  File "/home/airflow/.local/lib/python3.8/site-packages/airflow/operators/python.py", line 216, in execute_callable
    return self.python_callable(*self.op_args, **self.op_kwargs)
  File "/opt/airflow/dags/cdr.py", line 101, in load_to_s3
    wr.s3.to_parquet(
  File "/home/airflow/.local/lib/python3.8/site-packages/awswrangler/_config.py", line 712, in wrapper
    return function(**args)
  File "/home/airflow/.local/lib/python3.8/site-packages/awswrangler/_utils.py", line 179, in inner
    return func(*args, **kwargs)
  File "/home/airflow/.local/lib/python3.8/site-packages/awswrangler/s3/_write_parquet.py", line 723, in to_parquet
    return strategy.write(
  File "/home/airflow/.local/lib/python3.8/site-packages/awswrangler/s3/_write.py", line 376, in write
    paths, partitions_values = _to_dataset(
  File "/home/airflow/.local/lib/python3.8/site-packages/awswrangler/s3/_write_dataset.py", line 254, in _to_dataset
    paths = func(
  File "/home/airflow/.local/lib/python3.8/site-packages/awswrangler/_distributed.py", line 105, in wrapper
    return cls.dispatch_func(func)(*args, **kw)
  File "/home/airflow/.local/lib/python3.8/site-packages/awswrangler/s3/_write_parquet.py", line 219, in _to_parquet
    writer.write_table(table, **write_table_args)
  File "/usr/local/lib/python3.8/contextlib.py", line 120, in __exit__
    next(self.gen)
  File "/home/airflow/.local/lib/python3.8/site-packages/awswrangler/s3/_write_parquet.py", line 101, in _new_writer
    writer.close()
  File "/usr/local/lib/python3.8/contextlib.py", line 120, in __exit__
    next(self.gen)
  File "/home/airflow/.local/lib/python3.8/site-packages/awswrangler/s3/_fs.py", line 604, in open_s3_object
    s3obj.close()
  File "/home/airflow/.local/lib/python3.8/site-packages/awswrangler/s3/_fs.py", line 488, in close
    _utils.try_it(
  File "/home/airflow/.local/lib/python3.8/site-packages/awswrangler/_utils.py", line 790, in try_it
    return f(*args, **kwargs)
  File "/home/airflow/.local/lib/python3.8/site-packages/botocore/client.py", line 553, in _api_call
    return self._make_api_call(operation_name, kwargs)
  File "/home/airflow/.local/lib/python3.8/site-packages/botocore/client.py", line 1009, in _make_api_call
    raise error_class(parsed_response, operation_name)
botocore.exceptions.ClientError: An error occurred (SignatureDoesNotMatch) when calling the PutObject operation: The request signature we calculated does not match the signature you provided. Check your key and signing method.
[2025-08-01T22:33:37.080+0000] {taskinstance.py:1138} INFO - Marking task as UP_FOR_RETRY. dag_id=cdr_pipeline, task_id=load_to_s3, execution_date=20250801T205347, start_date=20250801T223333, end_date=20250801T223337
[2025-08-01T22:33:37.114+0000] {standard_task_runner.py:107} ERROR - Failed to execute job 27 for task load_to_s3 (An error occurred (SignatureDoesNotMatch) when calling the PutObject operation: The request signature we calculated does not match the signature you provided. Check your key and signing method.; 2522)
[2025-08-01T22:33:37.177+0000] {local_task_job_runner.py:234} INFO - Task exited with return code 1
[2025-08-01T22:33:37.215+0000] {taskinstance.py:3280} INFO - 0 downstream tasks scheduled from follow-on schedule check
